2025-03-19 15:38:57,986 - f1dashboard - ERROR - Database error: Database error in execute_query: Execution failed on sql 'SELECT DISTINCT session_id FROM overtakes': no such table: overtakes
Traceback (most recent call last):
  File "C:\Users\ylegkaya\AppData\Roaming\Python\Python312\site-packages\pandas\io\sql.py", line 2674, in execute
    cur.execute(sql, *args)
sqlite3.OperationalError: no such table: overtakes

The above exception was the direct cause of the following exception:

Traceback (most recent call last):
  File "D:\Dev\F1LiveDashboard\backend\db_connection.py", line 187, in execute_query
    df = pd.read_sql_query(query, self.conn, params=params)
         ^^^^^^^^^^^^^^^^^^^^^^^^^^^^^^^^^^^^^^^^^^^^^^^^^^
  File "C:\Users\ylegkaya\AppData\Roaming\Python\Python312\site-packages\pandas\io\sql.py", line 526, in read_sql_query
    return pandas_sql.read_query(
           ^^^^^^^^^^^^^^^^^^^^^^
  File "C:\Users\ylegkaya\AppData\Roaming\Python\Python312\site-packages\pandas\io\sql.py", line 2738, in read_query
    cursor = self.execute(sql, params)
             ^^^^^^^^^^^^^^^^^^^^^^^^^
  File "C:\Users\ylegkaya\AppData\Roaming\Python\Python312\site-packages\pandas\io\sql.py", line 2686, in execute
    raise ex from exc
pandas.errors.DatabaseError: Execution failed on sql 'SELECT DISTINCT session_id FROM overtakes': no such table: overtakes
2025-03-20 14:34:43,007 - f1dashboard - ERROR - Database error: Database query execution error: no such column: driver_name
Traceback (most recent call last):
  File "D:\Dev\F1LiveDashboard\backend\db_connection.py", line 170, in execute_query
    cursor.execute(query, params)
sqlite3.OperationalError: no such column: driver_name
2025-03-20 14:35:57,143 - f1dashboard - ERROR - Database error: Database query execution error: no such column: driver_name
Traceback (most recent call last):
  File "D:\Dev\F1LiveDashboard\backend\db_connection.py", line 170, in execute_query
    cursor.execute(query, params)
sqlite3.OperationalError: no such column: driver_name
2025-03-20 14:36:32,103 - f1dashboard - ERROR - Database error: Database query execution error: no such table: pit_stops
Traceback (most recent call last):
  File "D:\Dev\F1LiveDashboard\backend\db_connection.py", line 170, in execute_query
    cursor.execute(query, params)
sqlite3.OperationalError: no such table: pit_stops
2025-03-20 14:36:53,370 - f1dashboard - ERROR - Database error: Database query execution error: no such table: pit_stops
Traceback (most recent call last):
  File "D:\Dev\F1LiveDashboard\backend\db_connection.py", line 170, in execute_query
    cursor.execute(query, params)
sqlite3.OperationalError: no such table: pit_stops
2025-03-20 19:18:39,278 - f1dashboard - ERROR - Database error: Error retrieving lap times
Traceback (most recent call last):
  File "C:\Users\ylegkaya\AppData\Roaming\Python\Python312\site-packages\pandas\io\sql.py", line 2674, in execute
    cur.execute(sql, *args)
sqlite3.OperationalError: no such table: laps

The above exception was the direct cause of the following exception:

Traceback (most recent call last):
  File "D:\Dev\F1LiveDashboard\backend\data_service.py", line 204, in get_lap_times
    df = pd.read_sql_query(query, sqlite3.connect(self.sqlite_path), params=params)
         ^^^^^^^^^^^^^^^^^^^^^^^^^^^^^^^^^^^^^^^^^^^^^^^^^^^^^^^^^^^^^^^^^^^^^^^^^^
  File "C:\Users\ylegkaya\AppData\Roaming\Python\Python312\site-packages\pandas\io\sql.py", line 526, in read_sql_query
    return pandas_sql.read_query(
           ^^^^^^^^^^^^^^^^^^^^^^
  File "C:\Users\ylegkaya\AppData\Roaming\Python\Python312\site-packages\pandas\io\sql.py", line 2738, in read_query
    cursor = self.execute(sql, params)
             ^^^^^^^^^^^^^^^^^^^^^^^^^
  File "C:\Users\ylegkaya\AppData\Roaming\Python\Python312\site-packages\pandas\io\sql.py", line 2686, in execute
    raise ex from exc
pandas.errors.DatabaseError: Execution failed on sql 'SELECT * FROM laps WHERE session_id = ?': no such table: laps
2025-03-21 12:45:29,979 - f1dashboard - ERROR - Database error: Error retrieving lap times
Traceback (most recent call last):
  File "C:\Users\ylegkaya\AppData\Roaming\Python\Python312\site-packages\pandas\io\sql.py", line 2674, in execute
    cur.execute(sql, *args)
sqlite3.OperationalError: no such table: laps

The above exception was the direct cause of the following exception:

Traceback (most recent call last):
  File "D:\Dev\F1LiveDashboard\backend\data_service.py", line 204, in get_lap_times
    df = pd.read_sql_query(query, sqlite3.connect(self.sqlite_path), params=params)
         ^^^^^^^^^^^^^^^^^^^^^^^^^^^^^^^^^^^^^^^^^^^^^^^^^^^^^^^^^^^^^^^^^^^^^^^^^^
  File "C:\Users\ylegkaya\AppData\Roaming\Python\Python312\site-packages\pandas\io\sql.py", line 526, in read_sql_query
    return pandas_sql.read_query(
           ^^^^^^^^^^^^^^^^^^^^^^
  File "C:\Users\ylegkaya\AppData\Roaming\Python\Python312\site-packages\pandas\io\sql.py", line 2738, in read_query
    cursor = self.execute(sql, params)
             ^^^^^^^^^^^^^^^^^^^^^^^^^
  File "C:\Users\ylegkaya\AppData\Roaming\Python\Python312\site-packages\pandas\io\sql.py", line 2686, in execute
    raise ex from exc
pandas.errors.DatabaseError: Execution failed on sql 'SELECT * FROM laps WHERE session_id = ?': no such table: laps
2025-03-21 12:45:36,511 - f1dashboard - ERROR - Database error: Error retrieving lap times
Traceback (most recent call last):
  File "C:\Users\ylegkaya\AppData\Roaming\Python\Python312\site-packages\pandas\io\sql.py", line 2674, in execute
    cur.execute(sql, *args)
sqlite3.OperationalError: no such table: laps

The above exception was the direct cause of the following exception:

Traceback (most recent call last):
  File "D:\Dev\F1LiveDashboard\backend\data_service.py", line 204, in get_lap_times
    df = pd.read_sql_query(query, sqlite3.connect(self.sqlite_path), params=params)
         ^^^^^^^^^^^^^^^^^^^^^^^^^^^^^^^^^^^^^^^^^^^^^^^^^^^^^^^^^^^^^^^^^^^^^^^^^^
  File "C:\Users\ylegkaya\AppData\Roaming\Python\Python312\site-packages\pandas\io\sql.py", line 526, in read_sql_query
    return pandas_sql.read_query(
           ^^^^^^^^^^^^^^^^^^^^^^
  File "C:\Users\ylegkaya\AppData\Roaming\Python\Python312\site-packages\pandas\io\sql.py", line 2738, in read_query
    cursor = self.execute(sql, params)
             ^^^^^^^^^^^^^^^^^^^^^^^^^
  File "C:\Users\ylegkaya\AppData\Roaming\Python\Python312\site-packages\pandas\io\sql.py", line 2686, in execute
    raise ex from exc
pandas.errors.DatabaseError: Execution failed on sql 'SELECT * FROM laps WHERE session_id = ?': no such table: laps
2025-03-21 12:45:42,804 - f1dashboard - ERROR - Database error: Error retrieving lap times
Traceback (most recent call last):
  File "C:\Users\ylegkaya\AppData\Roaming\Python\Python312\site-packages\pandas\io\sql.py", line 2674, in execute
    cur.execute(sql, *args)
sqlite3.OperationalError: no such table: laps

The above exception was the direct cause of the following exception:

Traceback (most recent call last):
  File "D:\Dev\F1LiveDashboard\backend\data_service.py", line 204, in get_lap_times
    df = pd.read_sql_query(query, sqlite3.connect(self.sqlite_path), params=params)
         ^^^^^^^^^^^^^^^^^^^^^^^^^^^^^^^^^^^^^^^^^^^^^^^^^^^^^^^^^^^^^^^^^^^^^^^^^^
  File "C:\Users\ylegkaya\AppData\Roaming\Python\Python312\site-packages\pandas\io\sql.py", line 526, in read_sql_query
    return pandas_sql.read_query(
           ^^^^^^^^^^^^^^^^^^^^^^
  File "C:\Users\ylegkaya\AppData\Roaming\Python\Python312\site-packages\pandas\io\sql.py", line 2738, in read_query
    cursor = self.execute(sql, params)
             ^^^^^^^^^^^^^^^^^^^^^^^^^
  File "C:\Users\ylegkaya\AppData\Roaming\Python\Python312\site-packages\pandas\io\sql.py", line 2686, in execute
    raise ex from exc
pandas.errors.DatabaseError: Execution failed on sql 'SELECT * FROM laps WHERE session_id = ?': no such table: laps
2025-03-21 12:46:10,335 - f1dashboard - ERROR - Database error: Error retrieving lap times
Traceback (most recent call last):
  File "C:\Users\ylegkaya\AppData\Roaming\Python\Python312\site-packages\pandas\io\sql.py", line 2674, in execute
    cur.execute(sql, *args)
sqlite3.OperationalError: no such table: laps

The above exception was the direct cause of the following exception:

Traceback (most recent call last):
  File "D:\Dev\F1LiveDashboard\backend\data_service.py", line 204, in get_lap_times
    df = pd.read_sql_query(query, sqlite3.connect(self.sqlite_path), params=params)
         ^^^^^^^^^^^^^^^^^^^^^^^^^^^^^^^^^^^^^^^^^^^^^^^^^^^^^^^^^^^^^^^^^^^^^^^^^^
  File "C:\Users\ylegkaya\AppData\Roaming\Python\Python312\site-packages\pandas\io\sql.py", line 526, in read_sql_query
    return pandas_sql.read_query(
           ^^^^^^^^^^^^^^^^^^^^^^
  File "C:\Users\ylegkaya\AppData\Roaming\Python\Python312\site-packages\pandas\io\sql.py", line 2738, in read_query
    cursor = self.execute(sql, params)
             ^^^^^^^^^^^^^^^^^^^^^^^^^
  File "C:\Users\ylegkaya\AppData\Roaming\Python\Python312\site-packages\pandas\io\sql.py", line 2686, in execute
    raise ex from exc
pandas.errors.DatabaseError: Execution failed on sql 'SELECT * FROM laps WHERE session_id = ?': no such table: laps
2025-03-21 12:51:27,294 - f1dashboard - ERROR - Database error: Error retrieving lap times
Traceback (most recent call last):
  File "C:\Users\ylegkaya\AppData\Roaming\Python\Python312\site-packages\pandas\io\sql.py", line 2674, in execute
    cur.execute(sql, *args)
sqlite3.OperationalError: no such table: laps

The above exception was the direct cause of the following exception:

Traceback (most recent call last):
  File "D:\Dev\F1LiveDashboard\backend\data_service.py", line 204, in get_lap_times
    df = pd.read_sql_query(query, sqlite3.connect(self.sqlite_path), params=params)
         ^^^^^^^^^^^^^^^^^^^^^^^^^^^^^^^^^^^^^^^^^^^^^^^^^^^^^^^^^^^^^^^^^^^^^^^^^^
  File "C:\Users\ylegkaya\AppData\Roaming\Python\Python312\site-packages\pandas\io\sql.py", line 526, in read_sql_query
    return pandas_sql.read_query(
           ^^^^^^^^^^^^^^^^^^^^^^
  File "C:\Users\ylegkaya\AppData\Roaming\Python\Python312\site-packages\pandas\io\sql.py", line 2738, in read_query
    cursor = self.execute(sql, params)
             ^^^^^^^^^^^^^^^^^^^^^^^^^
  File "C:\Users\ylegkaya\AppData\Roaming\Python\Python312\site-packages\pandas\io\sql.py", line 2686, in execute
    raise ex from exc
pandas.errors.DatabaseError: Execution failed on sql 'SELECT * FROM laps WHERE session_id = ?': no such table: laps
2025-03-21 12:52:26,147 - f1dashboard - ERROR - Database error: Error retrieving lap times
Traceback (most recent call last):
  File "C:\Users\ylegkaya\AppData\Roaming\Python\Python312\site-packages\pandas\io\sql.py", line 2674, in execute
    cur.execute(sql, *args)
sqlite3.OperationalError: no such table: laps

The above exception was the direct cause of the following exception:

Traceback (most recent call last):
  File "D:\Dev\F1LiveDashboard\backend\data_service.py", line 204, in get_lap_times
    df = pd.read_sql_query(query, sqlite3.connect(self.sqlite_path), params=params)
         ^^^^^^^^^^^^^^^^^^^^^^^^^^^^^^^^^^^^^^^^^^^^^^^^^^^^^^^^^^^^^^^^^^^^^^^^^^
  File "C:\Users\ylegkaya\AppData\Roaming\Python\Python312\site-packages\pandas\io\sql.py", line 526, in read_sql_query
    return pandas_sql.read_query(
           ^^^^^^^^^^^^^^^^^^^^^^
  File "C:\Users\ylegkaya\AppData\Roaming\Python\Python312\site-packages\pandas\io\sql.py", line 2738, in read_query
    cursor = self.execute(sql, params)
             ^^^^^^^^^^^^^^^^^^^^^^^^^
  File "C:\Users\ylegkaya\AppData\Roaming\Python\Python312\site-packages\pandas\io\sql.py", line 2686, in execute
    raise ex from exc
pandas.errors.DatabaseError: Execution failed on sql 'SELECT * FROM laps WHERE session_id = ?': no such table: laps
2025-03-21 12:52:27,738 - f1dashboard - ERROR - Database error: Error retrieving lap times
Traceback (most recent call last):
  File "C:\Users\ylegkaya\AppData\Roaming\Python\Python312\site-packages\pandas\io\sql.py", line 2674, in execute
    cur.execute(sql, *args)
sqlite3.OperationalError: no such table: laps

The above exception was the direct cause of the following exception:

Traceback (most recent call last):
  File "D:\Dev\F1LiveDashboard\backend\data_service.py", line 204, in get_lap_times
    df = pd.read_sql_query(query, sqlite3.connect(self.sqlite_path), params=params)
         ^^^^^^^^^^^^^^^^^^^^^^^^^^^^^^^^^^^^^^^^^^^^^^^^^^^^^^^^^^^^^^^^^^^^^^^^^^
  File "C:\Users\ylegkaya\AppData\Roaming\Python\Python312\site-packages\pandas\io\sql.py", line 526, in read_sql_query
    return pandas_sql.read_query(
           ^^^^^^^^^^^^^^^^^^^^^^
  File "C:\Users\ylegkaya\AppData\Roaming\Python\Python312\site-packages\pandas\io\sql.py", line 2738, in read_query
    cursor = self.execute(sql, params)
             ^^^^^^^^^^^^^^^^^^^^^^^^^
  File "C:\Users\ylegkaya\AppData\Roaming\Python\Python312\site-packages\pandas\io\sql.py", line 2686, in execute
    raise ex from exc
pandas.errors.DatabaseError: Execution failed on sql 'SELECT * FROM laps WHERE session_id = ?': no such table: laps
2025-03-21 12:52:28,873 - f1dashboard - ERROR - Database error: Error retrieving lap times
Traceback (most recent call last):
  File "C:\Users\ylegkaya\AppData\Roaming\Python\Python312\site-packages\pandas\io\sql.py", line 2674, in execute
    cur.execute(sql, *args)
sqlite3.OperationalError: no such table: laps

The above exception was the direct cause of the following exception:

Traceback (most recent call last):
  File "D:\Dev\F1LiveDashboard\backend\data_service.py", line 204, in get_lap_times
    df = pd.read_sql_query(query, sqlite3.connect(self.sqlite_path), params=params)
         ^^^^^^^^^^^^^^^^^^^^^^^^^^^^^^^^^^^^^^^^^^^^^^^^^^^^^^^^^^^^^^^^^^^^^^^^^^
  File "C:\Users\ylegkaya\AppData\Roaming\Python\Python312\site-packages\pandas\io\sql.py", line 526, in read_sql_query
    return pandas_sql.read_query(
           ^^^^^^^^^^^^^^^^^^^^^^
  File "C:\Users\ylegkaya\AppData\Roaming\Python\Python312\site-packages\pandas\io\sql.py", line 2738, in read_query
    cursor = self.execute(sql, params)
             ^^^^^^^^^^^^^^^^^^^^^^^^^
  File "C:\Users\ylegkaya\AppData\Roaming\Python\Python312\site-packages\pandas\io\sql.py", line 2686, in execute
    raise ex from exc
pandas.errors.DatabaseError: Execution failed on sql 'SELECT * FROM laps WHERE session_id = ?': no such table: laps
2025-03-21 12:52:31,478 - f1dashboard - ERROR - Database error: Error retrieving lap times
Traceback (most recent call last):
  File "C:\Users\ylegkaya\AppData\Roaming\Python\Python312\site-packages\pandas\io\sql.py", line 2674, in execute
    cur.execute(sql, *args)
sqlite3.OperationalError: no such table: laps

The above exception was the direct cause of the following exception:

Traceback (most recent call last):
  File "D:\Dev\F1LiveDashboard\backend\data_service.py", line 204, in get_lap_times
    df = pd.read_sql_query(query, sqlite3.connect(self.sqlite_path), params=params)
         ^^^^^^^^^^^^^^^^^^^^^^^^^^^^^^^^^^^^^^^^^^^^^^^^^^^^^^^^^^^^^^^^^^^^^^^^^^
  File "C:\Users\ylegkaya\AppData\Roaming\Python\Python312\site-packages\pandas\io\sql.py", line 526, in read_sql_query
    return pandas_sql.read_query(
           ^^^^^^^^^^^^^^^^^^^^^^
  File "C:\Users\ylegkaya\AppData\Roaming\Python\Python312\site-packages\pandas\io\sql.py", line 2738, in read_query
    cursor = self.execute(sql, params)
             ^^^^^^^^^^^^^^^^^^^^^^^^^
  File "C:\Users\ylegkaya\AppData\Roaming\Python\Python312\site-packages\pandas\io\sql.py", line 2686, in execute
    raise ex from exc
pandas.errors.DatabaseError: Execution failed on sql 'SELECT * FROM laps WHERE session_id = ?': no such table: laps
2025-03-21 12:52:33,813 - f1dashboard - ERROR - Database error: Error retrieving lap times
Traceback (most recent call last):
  File "C:\Users\ylegkaya\AppData\Roaming\Python\Python312\site-packages\pandas\io\sql.py", line 2674, in execute
    cur.execute(sql, *args)
sqlite3.OperationalError: no such table: laps

The above exception was the direct cause of the following exception:

Traceback (most recent call last):
  File "D:\Dev\F1LiveDashboard\backend\data_service.py", line 204, in get_lap_times
    df = pd.read_sql_query(query, sqlite3.connect(self.sqlite_path), params=params)
         ^^^^^^^^^^^^^^^^^^^^^^^^^^^^^^^^^^^^^^^^^^^^^^^^^^^^^^^^^^^^^^^^^^^^^^^^^^
  File "C:\Users\ylegkaya\AppData\Roaming\Python\Python312\site-packages\pandas\io\sql.py", line 526, in read_sql_query
    return pandas_sql.read_query(
           ^^^^^^^^^^^^^^^^^^^^^^
  File "C:\Users\ylegkaya\AppData\Roaming\Python\Python312\site-packages\pandas\io\sql.py", line 2738, in read_query
    cursor = self.execute(sql, params)
             ^^^^^^^^^^^^^^^^^^^^^^^^^
  File "C:\Users\ylegkaya\AppData\Roaming\Python\Python312\site-packages\pandas\io\sql.py", line 2686, in execute
    raise ex from exc
pandas.errors.DatabaseError: Execution failed on sql 'SELECT * FROM laps WHERE session_id = ?': no such table: laps
2025-03-21 12:52:43,604 - f1dashboard - ERROR - Database error: Error retrieving lap times
Traceback (most recent call last):
  File "C:\Users\ylegkaya\AppData\Roaming\Python\Python312\site-packages\pandas\io\sql.py", line 2674, in execute
    cur.execute(sql, *args)
sqlite3.OperationalError: no such table: laps

The above exception was the direct cause of the following exception:

Traceback (most recent call last):
  File "D:\Dev\F1LiveDashboard\backend\data_service.py", line 204, in get_lap_times
    df = pd.read_sql_query(query, sqlite3.connect(self.sqlite_path), params=params)
         ^^^^^^^^^^^^^^^^^^^^^^^^^^^^^^^^^^^^^^^^^^^^^^^^^^^^^^^^^^^^^^^^^^^^^^^^^^
  File "C:\Users\ylegkaya\AppData\Roaming\Python\Python312\site-packages\pandas\io\sql.py", line 526, in read_sql_query
    return pandas_sql.read_query(
           ^^^^^^^^^^^^^^^^^^^^^^
  File "C:\Users\ylegkaya\AppData\Roaming\Python\Python312\site-packages\pandas\io\sql.py", line 2738, in read_query
    cursor = self.execute(sql, params)
             ^^^^^^^^^^^^^^^^^^^^^^^^^
  File "C:\Users\ylegkaya\AppData\Roaming\Python\Python312\site-packages\pandas\io\sql.py", line 2686, in execute
    raise ex from exc
pandas.errors.DatabaseError: Execution failed on sql 'SELECT * FROM laps WHERE session_id = ?': no such table: laps
